Workbook

Sheet Töflur
K1: Ár | L1: Launatafla | O1: Orlof | R1: Sérstakar álagsgreiðslur
A2: Ár | B2: 2026 | K2: 2024 | L2: Leiðsögumaður | O2: Án orlofs | P2: 0 | R2: Tungumála álag, eitt auka tungumál | S2: 0.2
A3: Launatafla | B3: Leiðsögumaður | K3: 2025 | L3: Ökuleiðsögumaður | O3: 24 dagar (10,17% orlof) | P3: 0.1017 | R3: Tungumála álag, tvö auka tungumál | S3: 0.4
A4: Orlof | B4: Án orlofs | K4: 2025 apríl | O4: 27 dagar (5 ára starfsreynsla) | P4: 0.1159 | R4: Tungumála álag, þrjú auka tungumál | S4: 0.6
C5: Tímakaup | K5: 2026 | O5: 30 dagar (10 ára starfsreynsla) | P5: 0.1304 | R5: Sérfræðiálag | S5: 0.25
B6: Mánaðarlaun | C6: Dagvinna | D6: Yfirvinna | E6: Stórhátíð | F6: Dagvinna með des/orlofsuppbót | K6: 2026 apríl | R6: Yfirleiðsögumaður | S6: 0.25
A7: Flokkur 1 grunnlaun | B7: =IF($B$3="Leiðsögumaður",Leiðsögn!B22,Ökuleiðsögn!B22) -> 526322.7 | C7: =IF($B$3="Leiðsögumaður",Leiðsögn!C22,Ökuleiðsögn!C22) -> 3239 | D7: =IF($B$3="Leiðsögumaður",Leiðsögn!D22,Ökuleiðsögn!D22) -> 5466 | E7: =IF($B$3="Leiðsögumaður",Leiðsögn!E22,Ökuleiðsögn!E22) -> 7237 | F7: =IF($B$3="Leiðsögumaður",Leiðsögn!F22,Ökuleiðsögn!F22) -> 3346 | K7: 2027
A8: Flokkur 2 grunnlaun | B8: =IF($B$3="Leiðsögumaður",Leiðsögn!B23,Ökuleiðsögn!B23) -> 526322.7 | C8: =IF($B$3="Leiðsögumaður",Leiðsögn!C23,Ökuleiðsögn!C23) -> 3239 | D8: =IF($B$3="Leiðsögumaður",Leiðsögn!D23,Ökuleiðsögn!D23) -> 5466 | E8: =IF($B$3="Leiðsögumaður",Leiðsögn!E23,Ökuleiðsögn!E23) -> 7237 | F8: =IF($B$3="Leiðsögumaður",Leiðsögn!F23,Ökuleiðsögn!F23) -> 3346
A9: Flokkur 2 eftir 1 ár | B9: =IF($B$3="Leiðsögumaður",Leiðsögn!B24,Ökuleiðsögn!B24) -> 528767.2 | C9: =IF($B$3="Leiðsögumaður",Leiðsögn!C24,Ökuleiðsögn!C24) -> 3254 | D9: =IF($B$3="Leiðsögumaður",Leiðsögn!D24,Ökuleiðsögn!D24) -> 5491 | E9: =IF($B$3="Leiðsögumaður",Leiðsögn!E24,Ökuleiðsögn!E24) -> 7271 | F9: =IF($B$3="Leiðsögumaður",Leiðsögn!F24,Ökuleiðsögn!F24) -> 3361
A10: Flokkur 3 grunnlaun | B10: =IF($B$3="Leiðsögumaður",Leiðsögn!B25,Ökuleiðsögn!B25) -> 529155.4 | C10: =IF($B$3="Leiðsögumaður",Leiðsögn!C25,Ökuleiðsögn!C25) -> 3256 | D10: =IF($B$3="Leiðsögumaður",Leiðsögn!D25,Ökuleiðsögn!D25) -> 5495 | E10: =IF($B$3="Leiðsögumaður",Leiðsögn!E25,Ökuleiðsögn!E25) -> 7276 | F10: =IF($B$3="Leiðsögumaður",Leiðsögn!F25,Ökuleiðsögn!F25) -> 3363
A11: Flokkur 3 eftir 1 ár | B11: =IF($B$3="Leiðsögumaður",Leiðsögn!B26,Ökuleiðsögn!B26) -> 540845.9 | C11: =IF($B$3="Leiðsögumaður",Leiðsögn!C26,Ökuleiðsögn!C26) -> 3328 | D11: =IF($B$3="Leiðsögumaður",Leiðsögn!D26,Ökuleiðsögn!D26) -> 5617 | E11: =IF($B$3="Leiðsögumaður",Leiðsögn!E26,Ökuleiðsögn!E26) -> 7437 | F11: =IF($B$3="Leiðsögumaður",Leiðsögn!F26,Ökuleiðsögn!F26) -> 3435
A12: Flokkur 3 eftir 3 ár | B12: =IF($B$3="Leiðsögumaður",Leiðsögn!B27,Ökuleiðsögn!B27) -> 556793.8 | C12: =IF($B$3="Leiðsögumaður",Leiðsögn!C27,Ökuleiðsögn!C27) -> 3426 | D12: =IF($B$3="Leiðsögumaður",Leiðsögn!D27,Ökuleiðsögn!D27) -> 5782 | E12: =IF($B$3="Leiðsögumaður",Leiðsögn!E27,Ökuleiðsögn!E27) -> 7656 | F12: =IF($B$3="Leiðsögumaður",Leiðsögn!F27,Ökuleiðsögn!F27) -> 3533
A13: Flokkur 3 eftir 5 ár | B13: =IF($B$3="Leiðsögumaður",Leiðsögn!B28,Ökuleiðsögn!B28) -> 560438.8 | C13: =IF($B$3="Leiðsögumaður",Leiðsögn!C28,Ökuleiðsögn!C28) -> 3449 | D13: =IF($B$3="Leiðsögumaður",Leiðsögn!D28,Ökuleiðsögn!D28) -> 5820 | E13: =IF($B$3="Leiðsögumaður",Leiðsögn!E28,Ökuleiðsögn!E28) -> 7706 | F13: =IF($B$3="Leiðsögumaður",Leiðsögn!F28,Ökuleiðsögn!F28) -> 3556
A14: Flokkur 4 grunnlaun | B14: =IF($B$3="Leiðsögumaður",Leiðsögn!B29,Ökuleiðsögn!B29) -> 533107.2 | C14: =IF($B$3="Leiðsögumaður",Leiðsögn!C29,Ökuleiðsögn!C29) -> 3281 | D14: =IF($B$3="Leiðsögumaður",Leiðsögn!D29,Ökuleiðsögn!D29) -> 5536 | E14: =IF($B$3="Leiðsögumaður",Leiðsögn!E29,Ökuleiðsögn!E29) -> 7330 | F14: =IF($B$3="Leiðsögumaður",Leiðsögn!F29,Ökuleiðsögn!F29) -> 3388
A15: Flokkur 4 eftir 1 ár | B15: =IF($B$3="Leiðsögumaður",Leiðsögn!B30,Ökuleiðsögn!B30) -> 553969.5 | C15: =IF($B$3="Leiðsögumaður",Leiðsögn!C30,Ökuleiðsögn!C30) -> 3409 | D15: =IF($B$3="Leiðsögumaður",Leiðsögn!D30,Ökuleiðsögn!D30) -> 5753 | E15: =IF($B$3="Leiðsögumaður",Leiðsögn!E30,Ökuleiðsögn!E30) -> 7617 | F15: =IF($B$3="Leiðsögumaður",Leiðsögn!F30,Ökuleiðsögn!F30) -> 3516
A16: Flokkur 4 eftir 3 ár | B16: =IF($B$3="Leiðsögumaður",Leiðsögn!B31,Ökuleiðsögn!B31) -> 570363.1 | C16: =IF($B$3="Leiðsögumaður",Leiðsögn!C31,Ökuleiðsögn!C31) -> 3510 | D16: =IF($B$3="Leiðsögumaður",Leiðsögn!D31,Ökuleiðsögn!D31) -> 5923 | E16: =IF($B$3="Leiðsögumaður",Leiðsögn!E31,Ökuleiðsögn!E31) -> 7842 | F16: =IF($B$3="Leiðsögumaður",Leiðsögn!F31,Ökuleiðsögn!F31) -> 3617
A17: Flokkur 4 eftir 5 ár | B17: =IF($B$3="Leiðsögumaður",Leiðsögn!B32,Ökuleiðsögn!B32) -> 578124.2 | C17: =IF($B$3="Leiðsögumaður",Leiðsögn!C32,Ökuleiðsögn!C32) -> 3558 | D17: =IF($B$3="Leiðsögumaður",Leiðsögn!D32,Ökuleiðsögn!D32) -> 6004 | E17: =IF($B$3="Leiðsögumaður",Leiðsögn!E32,Ökuleiðsögn!E32) -> 7949 | F17: =IF($B$3="Leiðsögumaður",Leiðsögn!F32,Ökuleiðsögn!F32) -> 3665
A21: Dagsferðir | B21: Lengd ferðar --> | D21: 4 klst. | E21: 4 klst. | F21: 5 klst. | G21: 5 klst. | H21: 6 klst. | I21: 6 klst. | J21: 7 klst. | K21: 7 klst. | L21: 8 klst. | M21: 8 klst. | N21: 9 klst | O21: 9 klst | P21: 10 klst. | Q21: 10 klst. | R21: 11 klst. | S21: 11 klst. | T21: 12 klst. | U21: 12 klst.
B22: Dagvinna | C22: Yfirvinna | D22: mán-föst | E22: lau-sun | F22: mán-föst | G22: lau-sun | H22: mán-föst | I22: lau-sun | J22: mán-föst | K22: lau-sun | L22: mán-föst | M22: lau-sun | N22: mán-föst | O22: lau-sun | P22: mán-föst | Q22: lau-sun | R22: mán-föst | S22: lau-sun | T22: mán-föst | U22: lau-sun
A23: Flokkur 1 grunnlaun | B23: =IF($B$3="Leiðsögumaður",Leiðsögn!B38,Ökuleiðsögn!B38) -> 3239 | C23: =IF($B$3="Leiðsögumaður",Leiðsögn!C38,Ökuleiðsögn!C38) -> 5466 | D23: =IF($B$3="Leiðsögumaður",Leiðsögn!D38,Ökuleiðsögn!D38) -> 12956 | E23: =IF($B$3="Leiðsögumaður",Leiðsögn!E38,Ökuleiðsögn!E38) -> 21864 | F23: =IF($B$3="Leiðsögumaður",Leiðsögn!F38,Ökuleiðsögn!F38) -> 16195 | G23: =IF($B$3="Leiðsögumaður",Leiðsögn!G38,Ökuleiðsögn!G38) -> 27330 | H23: =IF($B$3="Leiðsögumaður",Leiðsögn!H38,Ökuleiðsögn!H38) -> 19434 | I23: =IF($B$3="Leiðsögumaður",Leiðsögn!I38,Ökuleiðsögn!I38) -> 32796 | ... S23: =IF($B$3="Leiðsögumaður",Leiðsögn!S38,Ökuleiðsögn!S38) -> 60126
A24: Flokkur 2 grunnlaun | B24: =IF($B$3="Leiðsögumaður",Leiðsögn!B39,Ökuleiðsögn!B39) -> 3239 | C24: =IF($B$3="Leiðsögumaður",Leiðsögn!C39,Ökuleiðsögn!C39) -> 5466 | D24: =IF($B$3="Leiðsögumaður",Leiðsögn!D39,Ökuleiðsögn!D39) -> 12956 | E24: =IF($B$3="Leiðsögumaður",Leiðsögn!E39,Ökuleiðsögn!E39) -> 21864 | F24: =IF($B$3="Leiðsögumaður",Leiðsögn!F39,Ökuleiðsögn!F39) -> 16195 | G24: =IF($B$3="Leiðsögumaður",Leiðsögn!G39,Ökuleiðsögn!G39) -> 27330 | H24: =IF($B$3="Leiðsögumaður",Leiðsögn!H39,Ökuleiðsögn!H39) -> 19434 | I24: =IF($B$3="Leiðsögumaður",Leiðsögn!I39,Ökuleiðsögn!I39) -> 32796 | ... S24: =IF($B$3="Leiðsögumaður",Leiðsögn!S39,Ökuleiðsögn!S39) -> 60126
A25: Flokkur 2 eftir 1 ár | B25: =IF($B$3="Leiðsögumaður",Leiðsögn!B40,Ökuleiðsögn!B40) -> 3254 | C25: =IF($B$3="Leiðsögumaður",Leiðsögn!C40,Ökuleiðsögn!C40) -> 5491 | D25: =IF($B$3="Leiðsögumaður",Leiðsögn!D40,Ökuleiðsögn!D40) -> 13016 | E25: =IF($B$3="Leiðsögumaður",Leiðsögn!E40,Ökuleiðsögn!E40) -> 21964 | F25: =IF($B$3="Leiðsögumaður",Leiðsögn!F40,Ökuleiðsögn!F40) -> 16270 | G25: =IF($B$3="Leiðsögumaður",Leiðsögn!G40,Ökuleiðsögn!G40) -> 27455 | H25: =IF($B$3="Leiðsögumaður",Leiðsögn!H40,Ökuleiðsögn!H40) -> 19524 | I25: =IF($B$3="Leiðsögumaður",Leiðsögn!I40,Ökuleiðsögn!I40) -> 32946 | ... S25: =IF($B$3="Leiðsögumaður",Leiðsögn!S40,Ökuleiðsögn!S40) -> 60401
A26: Flokkur 3 grunnlaun | B26: =IF($B$3="Leiðsögumaður",Leiðsögn!B41,Ökuleiðsögn!B41) -> 3256 | C26: =IF($B$3="Leiðsögumaður",Leiðsögn!C41,Ökuleiðsögn!C41) -> 5495 | D26: =IF($B$3="Leiðsögumaður",Leiðsögn!D41,Ökuleiðsögn!D41) -> 13024 | E26: =IF($B$3="Leiðsögumaður",Leiðsögn!E41,Ökuleiðsögn!E41) -> 21980 | F26: =IF($B$3="Leiðsögumaður",Leiðsögn!F41,Ökuleiðsögn!F41) -> 16280 | G26: =IF($B$3="Leiðsögumaður",Leiðsögn!G41,Ökuleiðsögn!G41) -> 27475 | H26: =IF($B$3="Leiðsögumaður",Leiðsögn!H41,Ökuleiðsögn!H41) -> 19536 | I26: =IF($B$3="Leiðsögumaður",Leiðsögn!I41,Ökuleiðsögn!I41) -> 32970 | ... S26: =IF($B$3="Leiðsögumaður",Leiðsögn!S41,Ökuleiðsögn!S41) -> 60445
A27: Flokkur 3 eftir 1 ár | B27: =IF($B$3="Leiðsögumaður",Leiðsögn!B42,Ökuleiðsögn!B42) -> 3328 | C27: =IF($B$3="Leiðsögumaður",Leiðsögn!C42,Ökuleiðsögn!C42) -> 5617 | D27: =IF($B$3="Leiðsögumaður",Leiðsögn!D42,Ökuleiðsögn!D42) -> 13312 | E27: =IF($B$3="Leiðsögumaður",Leiðsögn!E42,Ökuleiðsögn!E42) -> 22468 | F27: =IF($B$3="Leiðsögumaður",Leiðsögn!F42,Ökuleiðsögn!F42) -> 16640 | G27: =IF($B$3="Leiðsögumaður",Leiðsögn!G42,Ökuleiðsögn!G42) -> 28085 | H27: =IF($B$3="Leiðsögumaður",Leiðsögn!H42,Ökuleiðsögn!H42) -> 19968 | I27: =IF($B$3="Leiðsögumaður",Leiðsögn!I42,Ökuleiðsögn!I42) -> 33702 | ... S27: =IF($B$3="Leiðsögumaður",Leiðsögn!S42,Ökuleiðsögn!S42) -> 61787
A28: Flokkur 3 eftir 3 ár | B28: =IF($B$3="Leiðsögumaður",Leiðsögn!B43,Ökuleiðsögn!B43) -> 3426 | C28: =IF($B$3="Leiðsögumaður",Leiðsögn!C43,Ökuleiðsögn!C43) -> 5782 | D28: =IF($B$3="Leiðsögumaður",Leiðsögn!D43,Ökuleiðsögn!D43) -> 13704 | E28: =IF($B$3="Leiðsögumaður",Leiðsögn!E43,Ökuleiðsögn!E43) -> 23128 | F28: =IF($B$3="Leiðsögumaður",Leiðsögn!F43,Ökuleiðsögn!F43) -> 17130 | G28: =IF($B$3="Leiðsögumaður",Leiðsögn!G43,Ökuleiðsögn!G43) -> 28910 | H28: =IF($B$3="Leiðsögumaður",Leiðsögn!H43,Ökuleiðsögn!H43) -> 20556 | I28: =IF($B$3="Leiðsögumaður",Leiðsögn!I43,Ökuleiðsögn!I43) -> 34692 | ... S28: =IF($B$3="Leiðsögumaður",Leiðsögn!S43,Ökuleiðsögn!S43) -> 63602
A29: Flokkur 3 eftir 5 ár | B29: =IF($B$3="Leiðsögumaður",Leiðsögn!B44,Ökuleiðsögn!B44) -> 3449 | C29: =IF($B$3="Leiðsögumaður",Leiðsögn!C44,Ökuleiðsögn!C44) -> 5820 | D29: =IF($B$3="Leiðsögumaður",Leiðsögn!D44,Ökuleiðsögn!D44) -> 13796 | E29: =IF($B$3="Leiðsögumaður",Leiðsögn!E44,Ökuleiðsögn!E44) -> 23280 | F29: =IF($B$3="Leiðsögumaður",Leiðsögn!F44,Ökuleiðsögn!F44) -> 17245 | G29: =IF($B$3="Leiðsögumaður",Leiðsögn!G44,Ökuleiðsögn!G44) -> 29100 | H29: =IF($B$3="Leiðsögumaður",Leiðsögn!H44,Ökuleiðsögn!H44) -> 20694 | I29: =IF($B$3="Leiðsögumaður",Leiðsögn!I44,Ökuleiðsögn!I44) -> 34920 | ... S29: =IF($B$3="Leiðsögumaður",Leiðsögn!S44,Ökuleiðsögn!S44) -> 64020
A30: Flokkur 4 grunnlaun | B30: =IF($B$3="Leiðsögumaður",Leiðsögn!B45,Ökuleiðsögn!B45) -> 3281 | C30: =IF($B$3="Leiðsögumaður",Leiðsögn!C45,Ökuleiðsögn!C45) -> 5536 | D30: =IF($B$3="Leiðsögumaður",Leiðsögn!D45,Ökuleiðsögn!D45) -> 13124 | E30: =IF($B$3="Leiðsögumaður",Leiðsögn!E45,Ökuleiðsögn!E45) -> 22144 | F30: =IF($B$3="Leiðsögumaður",Leiðsögn!F45,Ökuleiðsögn!F45) -> 16405 | G30: =IF($B$3="Leiðsögumaður",Leiðsögn!G45,Ökuleiðsögn!G45) -> 27680 | H30: =IF($B$3="Leiðsögumaður",Leiðsögn!H45,Ökuleiðsögn!H45) -> 19686 | I30: =IF($B$3="Leiðsögumaður",Leiðsögn!I45,Ökuleiðsögn!I45) -> 33216 | ... S30: =IF($B$3="Leiðsögumaður",Leiðsögn!S45,Ökuleiðsögn!S45) -> 60896
A31: Flokkur 4 eftir 1 ár | B31: =IF($B$3="Leiðsögumaður",Leiðsögn!B46,Ökuleiðsögn!B46) -> 3409 | C31: =IF($B$3="Leiðsögumaður",Leiðsögn!C46,Ökuleiðsögn!C46) -> 5753 | D31: =IF($B$3="Leiðsögumaður",Leiðsögn!D46,Ökuleiðsögn!D46) -> 13636 | E31: =IF($B$3="Leiðsögumaður",Leiðsögn!E46,Ökuleiðsögn!E46) -> 23012 | F31: =IF($B$3="Leiðsögumaður",Leiðsögn!F46,Ökuleiðsögn!F46) -> 17045 | G31: =IF($B$3="Leiðsögumaður",Leiðsögn!G46,Ökuleiðsögn!G46) -> 28765 | H31: =IF($B$3="Leiðsögumaður",Leiðsögn!H46,Ökuleiðsögn!H46) -> 20454 | I31: =IF($B$3="Leiðsögumaður",Leiðsögn!I46,Ökuleiðsögn!I46) -> 34518 | ... S31: =IF($B$3="Leiðsögumaður",Leiðsögn!S46,Ökuleiðsögn!S46) -> 63283
A32: Flokkur 4 eftir 3 ár | B32: =IF($B$3="Leiðsögumaður",Leiðsögn!B47,Ökuleiðsögn!B47) -> 3510 | C32: =IF($B$3="Leiðsögumaður",Leiðsögn!C47,Ökuleiðsögn!C47) -> 5923 | D32: =IF($B$3="Leiðsögumaður",Leiðsögn!D47,Ökuleiðsögn!D47) -> 14040 | E32: =IF($B$3="Leiðsögumaður",Leiðsögn!E47,Ökuleiðsögn!E47) -> 23692 | F32: =IF($B$3="Leiðsögumaður",Leiðsögn!F47,Ökuleiðsögn!F47) -> 17550 | G32: =IF($B$3="Leiðsögumaður",Leiðsögn!G47,Ökuleiðsögn!G47) -> 29615 | H32: =IF($B$3="Leiðsögumaður",Leiðsögn!H47,Ökuleiðsögn!H47) -> 21060 | I32: =IF($B$3="Leiðsögumaður",Leiðsögn!I47,Ökuleiðsögn!I47) -> 35538 | ... S32: =IF($B$3="Leiðsögumaður",Leiðsögn!S47,Ökuleiðsögn!S47) -> 65153
A33: Flokkur 4 eftir 5 ár | B33: =IF($B$3="Leiðsögumaður",Leiðsögn!B48,Ökuleiðsögn!B48) -> 3558 | C33: =IF($B$3="Leiðsögumaður",Leiðsögn!C48,Ökuleiðsögn!C48) -> 6004 | D33: =IF($B$3="Leiðsögumaður",Leiðsögn!D48,Ökuleiðsögn!D48) -> 14232 | E33: =IF($B$3="Leiðsögumaður",Leiðsögn!E48,Ökuleiðsögn!E48) -> 24016 | F33: =IF($B$3="Leiðsögumaður",Leiðsögn!F48,Ökuleiðsögn!F48) -> 17790 | G33: =IF($B$3="Leiðsögumaður",Leiðsögn!G48,Ökuleiðsögn!G48) -> 30020 | H33: =IF($B$3="Leiðsögumaður",Leiðsögn!H48,Ökuleiðsögn!H48) -> 21348 | I33: =IF($B$3="Leiðsögumaður",Leiðsögn!I48,Ökuleiðsögn!I48) -> 36024 | ... S33: =IF($B$3="Leiðsögumaður",Leiðsögn!S48,Ökuleiðsögn!S48) -> 66044
A34: Desember og orlofsuppbót | B34: =IF($B$3="Leiðsögumaður",Leiðsögn!B49,Ökuleiðsögn!B49) -> 107 | D34: =IF($B$3="Leiðsögumaður",Leiðsögn!D49,Ökuleiðsögn!D49) -> 428 | F34: =IF($B$3="Leiðsögumaður",Leiðsögn!F49,Ökuleiðsögn!F49) -> 535 | H34: =IF($B$3="Leiðsögumaður",Leiðsögn!H49,Ökuleiðsögn!H49) -> 642 | J34: =IF($B$3="Leiðsögumaður",Leiðsögn!J49,Ökuleiðsögn!J49) -> 749 | L34: =IF($B$3="Leiðsögumaður",Leiðsögn!L49,Ökuleiðsögn!L49) -> 802.5 | N34: =IF($B$3="Leiðsögumaður",Leiðsögn!N49,Ökuleiðsögn!N49) -> 802.5 | P34: =IF($B$3="Leiðsögumaður",Leiðsögn!P49,Ökuleiðsögn!P49) -> 802.5 | R34: =IF($B$3="Leiðsögumaður",Leiðsögn!R49,Ökuleiðsögn!R49) -> 802.5
A37: Langferðir
B39: Langferðir 11 klst./dag | C39: 2 dagar | D39: 2 dagar | E39: 2 dagar | F39: 4 dagar | G39: 4 dagar | H39: 4 dagar | I39: 6 dagar | J39: 6 dagar | K39: 8 dagar | L39: 8 dagar | M39: 10 dagar | N39: 10 dagar | O39: 10 dagar | P39: 12 dagar | Q39: 12 dagar | R39: 12 dagar | S39: 14 dagar
B40: Virkir dagar | C40: 2 | D40: 1 | E40: 0 | F40: 4 | G40: 3 | H40: 2 | I40: 5 | J40: 4 | K40: 6 | L40: 5 | M40: 8 | N40: 7 | O40: 6 | P40: 10 | Q40: 9 | R40: 8 | S40: 10
B41: Alm. frídagar | C41: 0 | D41: 1 | E41: 2 | F41: 0 | G41: 1 | H41: 2 | I41: 1 | J41: 2 | K41: 2 | L41: 3 | M41: 2 | N41: 3 | O41: 4 | P41: 2 | Q41: 3 | R41: 4 | S41: 4
A42: Flokkur 1 grunnlaun | C42: =IF($B$3="Leiðsögumaður",Leiðsögn!B58,Ökuleiðsögn!B58) -> 86847 | D42: =IF($B$3="Leiðsögumaður",Leiðsögn!C58,Ökuleiðsögn!C58) -> 103549.5 | E42: =IF($B$3="Leiðsögumaður",Leiðsögn!D58,Ökuleiðsögn!D58) -> 120252 | F42: =IF($B$3="Leiðsögumaður",Leiðsögn!E58,Ökuleiðsögn!E58) -> 173694 | G42: =IF($B$3="Leiðsögumaður",Leiðsögn!F58,Ökuleiðsögn!F58) -> 190396.5 | H42: =IF($B$3="Leiðsögumaður",Leiðsögn!G58,Ökuleiðsögn!G58) -> 207099 | I42: =IF($B$3="Leiðsögumaður",Leiðsögn!H58,Ökuleiðsögn!H58) -> 277243.5 | J42: =IF($B$3="Leiðsögumaður",Leiðsögn!I58,Ökuleiðsögn!I58) -> 293946 | ... S42: =IF($B$3="Leiðsögumaður",Leiðsögn!R58,Ökuleiðsögn!R58) -> 674739
A43: Flokkur 2 grunnlaun | C43: =IF($B$3="Leiðsögumaður",Leiðsögn!B59,Ökuleiðsögn!B59) -> 86847 | D43: =IF($B$3="Leiðsögumaður",Leiðsögn!C59,Ökuleiðsögn!C59) -> 103549.5 | E43: =IF($B$3="Leiðsögumaður",Leiðsögn!D59,Ökuleiðsögn!D59) -> 120252 | F43: =IF($B$3="Leiðsögumaður",Leiðsögn!E59,Ökuleiðsögn!E59) -> 173694 | G43: =IF($B$3="Leiðsögumaður",Leiðsögn!F59,Ökuleiðsögn!F59) -> 190396.5 | H43: =IF($B$3="Leiðsögumaður",Leiðsögn!G59,Ökuleiðsögn!G59) -> 207099 | I43: =IF($B$3="Leiðsögumaður",Leiðsögn!H59,Ökuleiðsögn!H59) -> 277243.5 | J43: =IF($B$3="Leiðsögumaður",Leiðsögn!I59,Ökuleiðsögn!I59) -> 293946 | ... S43: =IF($B$3="Leiðsögumaður",Leiðsögn!R59,Ökuleiðsögn!R59) -> 674739
A44: Flokkur 2 eftir 1 ár | C44: =IF($B$3="Leiðsögumaður",Leiðsögn!B60,Ökuleiðsögn!B60) -> 87247 | D44: =IF($B$3="Leiðsögumaður",Leiðsögn!C60,Ökuleiðsögn!C60) -> 104024.5 | E44: =IF($B$3="Leiðsögumaður",Leiðsögn!D60,Ökuleiðsögn!D60) -> 120802 | F44: =IF($B$3="Leiðsögumaður",Leiðsögn!E60,Ökuleiðsögn!E60) -> 174494 | G44: =IF($B$3="Leiðsögumaður",Leiðsögn!F60,Ökuleiðsögn!F60) -> 191271.5 | H44: =IF($B$3="Leiðsögumaður",Leiðsögn!G60,Ökuleiðsögn!G60) -> 208049 | I44: =IF($B$3="Leiðsögumaður",Leiðsögn!H60,Ökuleiðsögn!H60) -> 278518.5 | J44: =IF($B$3="Leiðsögumaður",Leiðsögn!I60,Ökuleiðsögn!I60) -> 295296 | ... S44: =IF($B$3="Leiðsögumaður",Leiðsögn!R60,Ökuleiðsögn!R60) -> 677839
A45: Flokkur 3 grunnlaun | C45: =IF($B$3="Leiðsögumaður",Leiðsögn!B61,Ökuleiðsögn!B61) -> 87305 | D45: =IF($B$3="Leiðsögumaður",Leiðsögn!C61,Ökuleiðsögn!C61) -> 104097.5 | E45: =IF($B$3="Leiðsögumaður",Leiðsögn!D61,Ökuleiðsögn!D61) -> 120890 | F45: =IF($B$3="Leiðsögumaður",Leiðsögn!E61,Ökuleiðsögn!E61) -> 174610 | G45: =IF($B$3="Leiðsögumaður",Leiðsögn!F61,Ökuleiðsögn!F61) -> 191402.5 | H45: =IF($B$3="Leiðsögumaður",Leiðsögn!G61,Ökuleiðsögn!G61) -> 208195 | I45: =IF($B$3="Leiðsögumaður",Leiðsögn!H61,Ökuleiðsögn!H61) -> 278707.5 | J45: =IF($B$3="Leiðsögumaður",Leiðsögn!I61,Ökuleiðsögn!I61) -> 295500 | ... S45: =IF($B$3="Leiðsögumaður",Leiðsögn!R61,Ökuleiðsögn!R61) -> 678305
A46: Flokkur 3 eftir 1 ár | C46: =IF($B$3="Leiðsögumaður",Leiðsögn!B62,Ökuleiðsögn!B62) -> 89239 | D46: =IF($B$3="Leiðsögumaður",Leiðsögn!C62,Ökuleiðsögn!C62) -> 106406.5 | E46: =IF($B$3="Leiðsögumaður",Leiðsögn!D62,Ökuleiðsögn!D62) -> 123574 | F46: =IF($B$3="Leiðsögumaður",Leiðsögn!E62,Ökuleiðsögn!E62) -> 178478 | G46: =IF($B$3="Leiðsögumaður",Leiðsögn!F62,Ökuleiðsögn!F62) -> 195645.5 | H46: =IF($B$3="Leiðsögumaður",Leiðsögn!G62,Ökuleiðsögn!G62) -> 212813 | I46: =IF($B$3="Leiðsögumaður",Leiðsögn!H62,Ökuleiðsögn!H62) -> 284884.5 | J46: =IF($B$3="Leiðsögumaður",Leiðsögn!I62,Ökuleiðsögn!I62) -> 302052 | ... S46: =IF($B$3="Leiðsögumaður",Leiðsögn!R62,Ökuleiðsögn!R62) -> 693343
...

Sheet Leiðsögn
A1: Ár valið | B1: =Töflur!B2 -> 2026
A2: Orlof | B2: =Töflur!B4 -> Án orlofs | C2: =VLOOKUP(B2,$Z$6:$AA$9,2,FALSE) -> 0
A5: Launatafla | I5: Mánaðarlaun | R5: Desember og orlofsuppbót | Z5: Orlof
B6: Mánaðarlaun | C6: Dagvinnukaup | D6: Yfirvinnukaup | E6: Stórhátíðakaup | F6: Dagvinnukaup með des/orlofsuppbót | J6: Núverandi | K6: 2024 | L6: 2025 | M6: 2025 apríl | N6: 2026 | O6: 2026 apríl | P6: 2027 | R6: Núverandi | S6: 2024 | T6: 2025 | U6: 2025 apríl | V6: 2026 | W6: 2026 apríl | X6: 2027 | Z6: Án orlofs | AA6: 0
A7: Flokkur 1 grunnlaun | B7: =INDEX($J$7:$P$17,MATCH(A7,$I$7:$I$17,0),MATCH($B$1,$J$6:$P$6,0)) -> 526322.7 | C7: =ROUND(B7/162.5,0) -> 3239 | D7: =ROUND(B7*0.010385,0) -> 5466 | E7: =ROUND(B7*0.01375,0) -> 7237 | F7: =+C7+HLOOKUP($B$1,$R$6:$X$7,2,FALSE) -> 3346 | I7: Flokkur 1 grunnlaun | J7: 444671 | K7: 470927 | L7: 497183 | M7: 500066.66 | N7: 526322.7 | O7: 526638.45 | P7: 551877.43 | R7: 95 | S7: 99 | T7: 103 | U7: 103 | V7: 107 | W7: 107 | X7: 110 | Z7: 24 dagar (10,17% orlof) | AA7: 0.1017
A8: Flokkur 2 grunnlaun | B8: =INDEX($J$7:$P$17,MATCH(A8,$I$7:$I$17,0),MATCH($B$1,$J$6:$P$6,0)) -> 526322.7 | C8: =ROUND(B8/162.5,0) -> 3239 | D8: =ROUND(B8*0.010385,0) -> 5466 | E8: =ROUND(B8*0.01375,0) -> 7237 | F8: =+C8+HLOOKUP($B$1,$R$6:$X$7,2,FALSE) -> 3346 | I8: Flokkur 2 grunnlaun | J8: 444671 | K8: 470927 | L8: 497183 | M8: 500066.66 | N8: 526322.7 | O8: 526638.45 | P8: 551877.43 | Z8: 27 dagar (5 ára starfsreynsla) | AA8: 0.1159
A9: Flokkur 2 eftir 1 ár | B9: =INDEX($J$7:$P$17,MATCH(A9,$I$7:$I$17,0),MATCH($B$1,$J$6:$P$6,0)) -> 528767.2 | C9: =ROUND(B9/162.5,0) -> 3254 | D9: =ROUND(B9*0.010385,0) -> 5491 | E9: =ROUND(B9*0.01375,0) -> 7271 | F9: =+C9+HLOOKUP($B$1,$R$6:$X$7,2,FALSE) -> 3361 | I9: Flokkur 2 eftir 1 ár | J9: 454605 | K9: 478355 | L9: 502105 | M9: 505017.21 | N9: 528767.2 | O9: 529084.47 | P9: 554301.41 | Z9: 30 dagar (10 ára starfsreynsla) | AA9: 0.1304
A10: Flokkur 3 grunnlaun | B10: =INDEX($J$7:$P$17,MATCH(A10,$I$7:$I$17,0),MATCH($B$1,$J$6:$P$6,0)) -> 529155.4 | C10: =ROUND(B10/162.5,0) -> 3256 | D10: =ROUND(B10*0.010385,0) -> 5495 | E10: =ROUND(B10*0.01375,0) -> 7276 | F10: =+C10+HLOOKUP($B$1,$R$6:$X$7,2,FALSE) -> 3363 | I10: Flokkur 3 grunnlaun | J10: 450618 | K10: 476225 | L10: 501276 | M10: 504183.4 | N10: 529155.4 | O10: 529472.89 | P10: 554844.54
A11: Flokkur 3 eftir 1 ár | B11: =INDEX($J$7:$P$17,MATCH(A11,$I$7:$I$17,0),MATCH($B$1,$J$6:$P$6,0)) -> 540845.9 | C11: =ROUND(B11/162.5,0) -> 3328 | D11: =ROUND(B11*0.010385,0) -> 5617 | E11: =ROUND(B11*0.01375,0) -> 7437 | F11: =+C11+HLOOKUP($B$1,$R$6:$X$7,2,FALSE) -> 3435 | I11: Flokkur 3 eftir 1 ár | J11: 466614 | K11: 490364 | L11: 514114 | M11: 517095.86 | N11: 540845.9 | O11: 541170.37 | P11: 564871.36
A12: Flokkur 3 eftir 3 ár | B12: =INDEX($J$7:$P$17,MATCH(A12,$I$7:$I$17,0),MATCH($B$1,$J$6:$P$6,0)) -> 556793.8 | C12: =ROUND(B12/162.5,0) -> 3426 | D12: =ROUND(B12*0.010385,0) -> 5782 | E12: =ROUND(B12*0.01375,0) -> 7656 | F12: =+C12+HLOOKUP($B$1,$R$6:$X$7,2,FALSE) -> 3533 | I12: Flokkur 3 eftir 3 ár | J12: 482470 | K12: 506220 | L12: 529970 | M12: 533043.83 | N12: 556793.8 | O12: 557127.9 | P12: 580819.33
A13: Flokkur 3 eftir 5 ár | B13: =INDEX($J$7:$P$17,MATCH(A13,$I$7:$I$17,0),MATCH($B$1,$J$6:$P$6,0)) -> 560438.8 | C13: =ROUND(B13/162.5,0) -> 3449 | D13: =ROUND(B13*0.010385,0) -> 5820 | E13: =ROUND(B13*0.01375,0) -> 7706 | F13: =+C13+HLOOKUP($B$1,$R$6:$X$7,2,FALSE) -> 3556 | I13: Flokkur 3 eftir 5 ár | J13: 486094 | K13: 509844 | L13: 533594 | M13: 536688.85 | N13: 560438.8 | O13: 560775.11 | P13: 584464.35
A14: Flokkur 4 grunnlaun | B14: =INDEX($J$7:$P$17,MATCH(A14,$I$7:$I$17,0),MATCH($B$1,$J$6:$P$6,0)) -> 533107.2 | C14: =ROUND(B14/162.5,0) -> 3281 | D14: =ROUND(B14*0.010385,0) -> 5536 | E14: =ROUND(B14*0.01375,0) -> 7330 | F14: =+C14+HLOOKUP($B$1,$R$6:$X$7,2,FALSE) -> 3388 | I14: Flokkur 4 grunnlaun | J14: 458920 | K14: 482670 | L14: 506420 | M14: 509357.24 | N14: 533107.2 | O14: 533427.1 | P14: 557132.74
A15: Flokkur 4 eftir 1 ár | B15: =INDEX($J$7:$P$17,MATCH(A15,$I$7:$I$17,0),MATCH($B$1,$J$6:$P$6,0)) -> 553969.5 | C15: =ROUND(B15/162.5,0) -> 3409 | D15: =ROUND(B15*0.010385,0) -> 5753 | E15: =ROUND(B15*0.01375,0) -> 7617 | F15: =+C15+HLOOKUP($B$1,$R$6:$X$7,2,FALSE) -> 3516 | I15: Flokkur 4 eftir 1 ár | J15: 479662 | K15: 503412 | L15: 527162 | M15: 530219.54 | N15: 553969.5 | O15: 554301.92 | P15: 577995.04
A16: Flokkur 4 eftir 3 ár | B16: =INDEX($J$7:$P$17,MATCH(A16,$I$7:$I$17,0),MATCH($B$1,$J$6:$P$6,0)) -> 570363.1 | C16: =ROUND(B16/162.5,0) -> 3510 | D16: =ROUND(B16*0.010385,0) -> 5923 | E16: =ROUND(B16*0.01375,0) -> 7842 | F16: =+C16+HLOOKUP($B$1,$R$6:$X$7,2,FALSE) -> 3617 | I16: Flokkur 4 eftir 3 ár | J16: 495961 | K16: 519711 | L16: 543461 | M16: 546613.07 | N16: 570363.1 | O16: 570705.29 | P16: 594388.57
A17: Flokkur 4 eftir 5 ár | B17: =INDEX($J$7:$P$17,MATCH(A17,$I$7:$I$17,0),MATCH($B$1,$J$6:$P$6,0)) -> 578124.2 | C17: =ROUND(B17/162.5,0) -> 3558 | D17: =ROUND(B17*0.010385,0) -> 6004 | E17: =ROUND(B17*0.01375,0) -> 7949 | F17: =+C17+HLOOKUP($B$1,$R$6:$X$7,2,FALSE) -> 3665 | I17: Flokkur 4 eftir 5 ár | J17: 499686 | K17: 524436 | L17: 549686 | M17: 552874.18 | N17: 578124.2 | O17: 578471.05 | P17: 603667.08
A20: Launatafla með orlofi
B21: Mánaðarlaun | C21: Dagvinnukaup | D21: Yfirvinnukaup | E21: Stórhátíðakaup | F21: Dagvinnukaup með des/orlofsuppbót
A22: Flokkur 1 grunnlaun | B22: =B7*(1+$C$2) -> 526322.7 | C22: =ROUND(B22/162.5,0) -> 3239 | D22: =ROUND(B22*0.010385,0) -> 5466 | E22: =ROUND(B22*0.01375,0) -> 7237 | F22: =+C22+HLOOKUP($B$1,$R$6:$X$7,2,FALSE) -> 3346
A23: Flokkur 2 grunnlaun | B23: =B8*(1+$C$2) -> 526322.7 | C23: =ROUND(B23/162.5,0) -> 3239 | D23: =ROUND(B23*0.010385,0) -> 5466 | E23: =ROUND(B23*0.01375,0) -> 7237 | F23: =+C23+HLOOKUP($B$1,$R$6:$X$7,2,FALSE) -> 3346
A24: Flokkur 2 eftir 1 ár | B24: =B9*(1+$C$2) -> 528767.2 | C24: =ROUND(B24/162.5,0) -> 3254 | D24: =ROUND(B24*0.010385,0) -> 5491 | E24: =ROUND(B24*0.01375,0) -> 7271 | F24: =+C24+HLOOKUP($B$1,$R$6:$X$7,2,FALSE) -> 3361
A25: Flokkur 3 grunnlaun | B25: =B10*(1+$C$2) -> 529155.4 | C25: =ROUND(B25/162.5,0) -> 3256 | D25: =ROUND(B25*0.010385,0) -> 5495 | E25: =ROUND(B25*0.01375,0) -> 7276 | F25: =+C25+HLOOKUP($B$1,$R$6:$X$7,2,FALSE) -> 3363
A26: Flokkur 3 eftir 1 ár | B26: =B11*(1+$C$2) -> 540845.9 | C26: =ROUND(B26/162.5,0) -> 3328 | D26: =ROUND(B26*0.010385,0) -> 5617 | E26: =ROUND(B26*0.01375,0) -> 7437 | F26: =+C26+HLOOKUP($B$1,$R$6:$X$7,2,FALSE) -> 3435
A27: Flokkur 3 eftir 3 ár | B27: =B12*(1+$C$2) -> 556793.8 | C27: =ROUND(B27/162.5,0) -> 3426 | D27: =ROUND(B27*0.010385,0) -> 5782 | E27: =ROUND(B27*0.01375,0) -> 7656 | F27: =+C27+HLOOKUP($B$1,$R$6:$X$7,2,FALSE) -> 3533
A28: Flokkur 3 eftir 5 ár | B28: =B13*(1+$C$2) -> 560438.8 | C28: =ROUND(B28/162.5,0) -> 3449 | D28: =ROUND(B28*0.010385,0) -> 5820 | E28: =ROUND(B28*0.01375,0) -> 7706 | F28: =+C28+HLOOKUP($B$1,$R$6:$X$7,2,FALSE) -> 3556
A29: Flokkur 4 grunnlaun | B29: =B14*(1+$C$2) -> 533107.2 | C29: =ROUND(B29/162.5,0) -> 3281 | D29: =ROUND(B29*0.010385,0) -> 5536 | E29: =ROUND(B29*0.01375,0) -> 7330 | F29: =+C29+HLOOKUP($B$1,$R$6:$X$7,2,FALSE) -> 3388
A30: Flokkur 4 eftir 1 ár | B30: =B15*(1+$C$2) -> 553969.5 | C30: =ROUND(B30/162.5,0) -> 3409 | D30: =ROUND(B30*0.010385,0) -> 5753 | E30: =ROUND(B30*0.01375,0) -> 7617 | F30: =+C30+HLOOKUP($B$1,$R$6:$X$7,2,FALSE) -> 3516
A31: Flokkur 4 eftir 3 ár | B31: =B16*(1+$C$2) -> 570363.1 | C31: =ROUND(B31/162.5,0) -> 3510 | D31: =ROUND(B31*0.010385,0) -> 5923 | E31: =ROUND(B31*0.01375,0) -> 7842 | F31: =+C31+HLOOKUP($B$1,$R$6:$X$7,2,FALSE) -> 3617
A32: Flokkur 4 eftir 5 ár | B32: =B17*(1+$C$2) -> 578124.2 | C32: =ROUND(B32/162.5,0) -> 3558 | D32: =ROUND(B32*0.010385,0) -> 6004 | E32: =ROUND(B32*0.01375,0) -> 7949 | F32: =+C32+HLOOKUP($B$1,$R$6:$X$7,2,FALSE) -> 3665
A35: Dagsferðir
C36: Lengd ferðar -> | D36: 4 kist. | E36: 4 kist. | F36: 5 klst. | G36: 5 klst. | H36: 6 klst. | I36: 6 klst. | J36: 7 klst. | K36: 7 klst. | L36: 8 klst. | M36: 8 klst. | N36: 9 klst | O36: 9 klst | P36: 10 klst. | Q36: 10 klst. | R36: 11 klst. | S36: 11 klst. | T36: 12 klst. | U36: 12 klst.
B37: Dagvinna | C37: Yfirvinna | D37: mán-föst | E37: lau-sun | F37: mán-föst | G37: lau-sun | H37: mán-föst | I37: lau-sun | J37: mán-föst | K37: lau-sun | L37: mán-föst | M37: lau-sun | N37: mán-föst | O37: lau-sun | P37: mán-föst | Q37: lau-sun | R37: mán-föst | S37: lau-sun | T37: mán-föst | U37: lau-sun
A38: Flokkur 1 grunnlaun | B38: =C22 -> 3239 | C38: =D22 -> 5466 | D38: =D$51*($B38) -> 12956 | E38: =E$51*($C38) -> 21864 | F38: =F$51*($B38) -> 16195 | G38: =G$51*($C38) -> 27330 | H38: =H$51*($B38) -> 19434 | I38: =I$51*($C38) -> 32796 | J38: =J$51*($B38) -> 22673 | K38: =K$51*($C38) -> 38262 | L38: =MIN(L$51,7.5)*$B38+(L$51-7.5)*$C38 -> 27025.5 | M38: =M$51*($C38) -> 43728 | N38: =MIN(N$51,7.5)*$B38+(N$51-7.5)*$C38 -> 32491.5 | O38: =O$51*($C38) -> 49194 | P38: =MIN(P$51,7.5)*$B38+(P$51-7.5)*$C38 -> 37957.5 | Q38: =Q$51*($C38) -> 54660 | R38: =MIN(R$51,7.5)*$B38+(R$51-7.5)*$C38 -> 43423.5 | S38: =S$51*($C38) -> 60126 | T38: =MIN(T$51,7.5)*$B38+(T$51-7.5)*$C38 -> 48889.5 | U38: =U$51*($C38) -> 65592
A39: Flokkur 2 grunnlaun | B39: =C23 -> 3239 | C39: =D23 -> 5466 | D39: =D$51*($B39) -> 12956 | E39: =E$51*($C39) -> 21864 | F39: =F$51*($B39) -> 16195 | G39: =G$51*($C39) -> 27330 | H39: =H$51*($B39) -> 19434 | I39: =I$51*($C39) -> 32796 | J39: =J$51*($B39) -> 22673 | K39: =K$51*($C39) -> 38262 | L39: =MIN(L$51,7.5)*$B39+(L$51-7.5)*$C39 -> 27025.5 | M39: =M$51*($C39) -> 43728 | N39: =MIN(N$51,7.5)*$B39+(N$51-7.5)*$C39 -> 32491.5 | O39: =O$51*($C39) -> 49194 | P39: =MIN(P$51,7.5)*$B39+(P$51-7.5)*$C39 -> 37957.5 | Q39: =Q$51*($C39) -> 54660 | R39: =MIN(R$51,7.5)*$B39+(R$51-7.5)*$C39 -> 43423.5 | S39: =S$51*($C39) -> 60126 | T39: =MIN(T$51,7.5)*$B39+(T$51-7.5)*$C39 -> 48889.5 | U39: =U$51*($C39) -> 65592
A40: Flokkur 2 eftir 1 ár | B40: =C24 -> 3254 | C40: =D24 -> 5491 | D40: =D$51*($B40) -> 13016 | E40: =E$51*($C40) -> 21964 | F40: =F$51*($B40) -> 16270 | G40: =G$51*($C40) -> 27455 | H40: =H$51*($B40) -> 19524 | I40: =I$51*($C40) -> 32946 | J40: =J$51*($B40) -> 22778 | K40: =K$51*($C40) -> 38437 | L40: =MIN(L$51,7.5)*$B40+(L$51-7.5)*$C40 -> 27150.5 | M40: =M$51*($C40) -> 43928 | N40: =MIN(N$51,7.5)*$B40+(N$51-7.5)*$C40 -> 32641.5 | O40: =O$51*($C40) -> 49419 | P40: =MIN(P$51,7.5)*$B40+(P$51-7.5)*$C40 -> 38132.5 | Q40: =Q$51*($C40) -> 54910 | R40: =MIN(R$51,7.5)*$B40+(R$51-7.5)*$C40 -> 43623.5 | S40: =S$51*($C40) -> 60401 | T40: =MIN(T$51,7.5)*$B40+(T$51-7.5)*$C40 -> 49114.5 | U40: =U$51*($C40) -> 65892
A41: Flokkur 3 grunnlaun | B41: =C25 -> 3256 | C41: =D25 -> 5495 | D41: =D$51*($B41) -> 13024 | E41: =E$51*($C41) -> 21980 | F41: =F$51*($B41) -> 16280 | G41: =G$51*($C41) -> 27475 | H41: =H$51*($B41) -> 19536 | I41: =I$51*($C41) -> 32970 | J41: =J$51*($B41) -> 22792 | K41: =K$51*($C41) -> 38465 | L41: =MIN(L$51,7.5)*$B41+(L$51-7.5)*$C41 -> 27167.5 | M41: =M$51*($C41) -> 43960 | N41: =MIN(N$51,7.5)*$B41+(N$51-7.5)*$C41 -> 32662.5 | O41: =O$51*($C41) -> 49455 | P41: =MIN(P$51,7.5)*$B41+(P$51-7.5)*$C41 -> 38157.5 | Q41: =Q$51*($C41) -> 54950 | R41: =MIN(R$51,7.5)*$B41+(R$51-7.5)*$C41 -> 43652.5 | S41: =S$51*($C41) -> 60445 | T41: =MIN(T$51,7.5)*$B41+(T$51-7.5)*$C41 -> 49147.5 | U41: =U$51*($C41) -> 65940
A42: Flokkur 3 eftir 1 ár | B42: =C26 -> 3328 | C42: =D26 -> 5617 | D42: =D$51*($B42) -> 13312 | E42: =E$51*($C42) -> 22468 | F42: =F$51*($B42) -> 16640 | G42: =G$51*($C42) -> 28085 | H42: =H$51*($B42) -> 19968 | I42: =I$51*($C42) -> 33702 | J42: =J$51*($B42) -> 23296 | K42: =K$51*($C42) -> 39319 | L42: =MIN(L$51,7.5)*$B42+(L$51-7.5)*$C42 -> 27768.5 | M42: =M$51*($C42) -> 44936 | N42: =MIN(N$51,7.5)*$B42+(N$51-7.5)*$C42 -> 33385.5 | O42: =O$51*($C42) -> 50553 | P42: =MIN(P$51,7.5)*$B42+(P$51-7.5)*$C42 -> 39002.5 | Q42: =Q$51*($C42) -> 56170 | R42: =MIN(R$51,7.5)*$B42+(R$51-7.5)*$C42 -> 44619.5 | S42: =S$51*($C42) -> 61787 | T42: =MIN(T$51,7.5)*$B42+(T$51-7.5)*$C42 -> 50236.5 | U42: =U$51*($C42) -> 67404
A43: Flokkur 3 eftir 3 ár | B43: =C27 -> 3426 | C43: =D27 -> 5782 | D43: =D$51*($B43) -> 13704 | E43: =E$51*($C43) -> 23128 | F43: =F$51*($B43) -> 17130 | G43: =G$51*($C43) -> 28910 | H43: =H$51*($B43) -> 20556 | I43: =I$51*($C43) -> 34692 | J43: =J$51*($B43) -> 23982 | K43: =K$51*($C43) -> 40474 | L43: =MIN(L$51,7.5)*$B43+(L$51-7.5)*$C43 -> 28586 | M43: =M$51*($C43) -> 46256 | N43: =MIN(N$51,7.5)*$B43+(N$51-7.5)*$C43 -> 34368 | O43: =O$51*($C43) -> 52038 | P43: =MIN(P$51,7.5)*$B43+(P$51-7.5)*$C43 -> 40150 | Q43: =Q$51*($C43) -> 57820 | R43: =MIN(R$51,7.5)*$B43+(R$51-7.5)*$C43 -> 45932 | S43: =S$51*($C43) -> 63602 | T43: =MIN(T$51,7.5)*$B43+(T$51-7.5)*$C43 -> 51714 | U43: =U$51*($C43) -> 69384
A44: Flokkur 3 eftir 5 ár | B44: =C28 -> 3449 | C44: =D28 -> 5820 | D44: =D$51*($B44) -> 13796 | E44: =E$51*($C44) -> 23280 | F44: =F$51*($B44) -> 17245 | G44: =G$51*($C44) -> 29100 | H44: =H$51*($B44) -> 20694 | I44: =I$51*($C44) -> 34920 | J44: =J$51*($B44) -> 24143 | K44: =K$51*($C44) -> 40740 | L44: =MIN(L$51,7.5)*$B44+(L$51-7.5)*$C44 -> 28777.5 | M44: =M$51*($C44) -> 46560 | N44: =MIN(N$51,7.5)*$B44+(N$51-7.5)*$C44 -> 34597.5 | O44: =O$51*($C44) -> 52380 | P44: =MIN(P$51,7.5)*$B44+(P$51-7.5)*$C44 -> 40417.5 | Q44: =Q$51*($C44) -> 58200 | R44: =MIN(R$51,7.5)*$B44+(R$51-7.5)*$C44 -> 46237.5 | S44: =S$51*($C44) -> 64020 | T44: =MIN(T$51,7.5)*$B44+(T$51-7.5)*$C44 -> 52057.5 | U44: =U$51*($C44) -> 69840
A45: Flokkur 4 grunnlaun | B45: =C29 -> 3281 | C45: =D29 -> 5536 | D45: =D$51*($B45) -> 13124 | E45: =E$51*($C45) -> 22144 | F45: =F$51*($B45) -> 16405 | G45: =G$51*($C45) -> 27680 | H45: =H$51*($B45) -> 19686 | I45: =I$51*($C45) -> 33216 | J45: =J$51*($B45) -> 22967 | K45: =K$51*($C45) -> 38752 | L45: =MIN(L$51,7.5)*$B45+(L$51-7.5)*$C45 -> 27375.5 | M45: =M$51*($C45) -> 44288 | N45: =MIN(N$51,7.5)*$B45+(N$51-7.5)*$C45 -> 32911.5 | O45: =O$51*($C45) -> 49824 | P45: =MIN(P$51,7.5)*$B45+(P$51-7.5)*$C45 -> 38447.5 | Q45: =Q$51*($C45) -> 55360 | R45: =MIN(R$51,7.5)*$B45+(R$51-7.5)*$C45 -> 43983.5 | S45: =S$51*($C45) -> 60896 | T45: =MIN(T$51,7.5)*$B45+(T$51-7.5)*$C45 -> 49519.5 | U45: =U$51*($C45) -> 66432
A46: Flokkur 4 eftir 1 ár | B46: =C30 -> 3409 | C46: =D30 -> 5753 | D46: =D$51*($B46) -> 13636 | E46: =E$51*($C46) -> 23012 | F46: =F$51*($B46) -> 17045 | G46: =G$51*($C46) -> 28765 | H46: =H$51*($B46) -> 20454 | I46: =I$51*($C46) -> 34518 | J46: =J$51*($B46) -> 23863 | K46: =K$51*($C46) -> 40271 | L46: =MIN(L$51,7.5)*$B46+(L$51-7.5)*$C46 -> 28444 | M46: =M$51*($C46) -> 46024 | N46: =MIN(N$51,7.5)*$B46+(N$51-7.5)*$C46 -> 34197 | O46: =O$51*($C46) -> 51777 | P46: =MIN(P$51,7.5)*$B46+(P$51-7.5)*$C46 -> 39950 | Q46: =Q$51*($C46) -> 57530 | R46: =MIN(R$51,7.5)*$B46+(R$51-7.5)*$C46 -> 45703 | S46: =S$51*($C46) -> 63283 | T46: =MIN(T$51,7.5)*$B46+(T$51-7.5)*$C46 -> 51456 | U46: =U$51*($C46) -> 69036
...

Sheet Ökuleiðsögn
A1: Ár valið | B1: =Töflur!B2 -> 2026
A2: Orlof | B2: =Töflur!B4 -> Án orlofs | C2: =VLOOKUP(B2,Leiðsögn!$Z$6:$AA$9,2,FALSE) -> 0
A5: Launatafla | C5: Tímakaup | I5: Mánaðarlaun | R5: Desember og orlofsuppbót
B6: Mánaðarlaun | C6: Dagvinnukaup | D6: Yfirvinnukaup | E6: Stórhátíðakaup | F6: Dagvinnukaup með des/orlofsuppbót | J6: Núverandi | K6: 2024 | L6: 2025 | M6: 2025 apríl | N6: 2026 | O6: 2026 apríl | P6: 2027 | R6: Núverandi | S6: 2024 | T6: 2025 | U6: 2026 | V6: 2026 apríl | W6: 2027
A7: Flokkur 1 grunnlaun | B7: =INDEX($J$7:$P$17,MATCH(A7,$I$7:$I$17,0),MATCH($B$1,$J$6:$P$6,0)) -> 789484 | C7: =ROUND(B7/162.5,0) -> 4858 | D7: =ROUND(B7*0.010385,0) -> 8199 | E7: =ROUND(B7*0.01375,0) -> 10855 | F7: =+C7+HLOOKUP($B$1,$R$6:$W$7,2,FALSE) -> 4965 | I7: Flokkur 1 grunnlaun | J7: 667006 | K7: 706390.5 | L7: 745774.5 | M7: 750099.99 | N7: 789484 | O7: 789958 | P7: 827816.15 | R7: 95 | S7: 99 | T7: 103 | U7: 107 | V7: 107 | W7: 110
A8: Flokkur 2 grunnlaun | B8: =INDEX($J$7:$P$17,MATCH(A8,$I$7:$I$17,0),MATCH($B$1,$J$6:$P$6,0)) -> 789484 | C8: =ROUND(B8/162.5,0) -> 4858 | D8: =ROUND(B8*0.010385,0) -> 8199 | E8: =ROUND(B8*0.01375,0) -> 10855 | F8: =+C8+HLOOKUP($B$1,$R$6:$W$7,2,FALSE) -> 4965 | I8: Flokkur 2 grunnlaun | J8: 667006 | K8: 706390.5 | L8: 745774.5 | M8: 750099.99 | N8: 789484 | O8: 789958 | P8: 827816.15
A9: Flokkur 2 eftir 1 ár | B9: =INDEX($J$7:$P$17,MATCH(A9,$I$7:$I$17,0),MATCH($B$1,$J$6:$P$6,0)) -> 793150.8 | C9: =ROUND(B9/162.5,0) -> 4881 | D9: =ROUND(B9*0.010385,0) -> 8237 | E9: =ROUND(B9*0.01375,0) -> 10906 | F9: =+C9+HLOOKUP($B$1,$R$6:$W$7,2,FALSE) -> 4988 | I9: Flokkur 2 eftir 1 ár | J9: 681907 | K9: 717532.5 | L9: 753157.5 | M9: 757525.81 | N9: 793150.8 | O9: 793627 | P9: 831452.11
A10: Flokkur 3 grunnlaun | B10: =INDEX($J$7:$P$17,MATCH(A10,$I$7:$I$17,0),MATCH($B$1,$J$6:$P$6,0)) -> 793733.1 | C10: =ROUND(B10/162.5,0) -> 4885 | D10: =ROUND(B10*0.010385,0) -> 8243 | E10: =ROUND(B10*0.01375,0) -> 10914 | F10: =+C10+HLOOKUP($B$1,$R$6:$W$7,2,FALSE) -> 4992 | I10: Flokkur 3 grunnlaun | J10: 675927 | K10: 714337.5 | L10: 751914 | M10: 756275.1 | N10: 793733.1 | O10: 794209 | P10: 832266.81
A11: Flokkur 3 eftir 1 ár | B11: =INDEX($J$7:$P$17,MATCH(A11,$I$7:$I$17,0),MATCH($B$1,$J$6:$P$6,0)) -> 811268.8 | C11: =ROUND(B11/162.5,0) -> 4992 | D11: =ROUND(B11*0.010385,0) -> 8425 | E11: =ROUND(B11*0.01375,0) -> 11155 | F11: =+C11+HLOOKUP($B$1,$R$6:$W$7,2,FALSE) -> 5099 | I11: Flokkur 3 eftir 1 ár | J11: 699921 | K11: 735546 | L11: 771171 | M11: 775643.79 | N11: 811268.8 | O11: 811756 | P11: 847307.04
A12: Flokkur 3 eftir 3 ár | B12: =INDEX($J$7:$P$17,MATCH(A12,$I$7:$I$17,0),MATCH($B$1,$J$6:$P$6,0)) -> 835190.7 | C12: =ROUND(B12/162.5,0) -> 5140 | D12: =ROUND(B12*0.010385,0) -> 8673 | E12: =ROUND(B12*0.01375,0) -> 11484 | F12: =+C12+HLOOKUP($B$1,$R$6:$W$7,2,FALSE) -> 5247 | I12: Flokkur 3 eftir 3 ár | J12: 723705 | K12: 759330 | L12: 794955 | M12: 799565.74 | N12: 835190.7 | O12: 835692 | P12: 871228.99
A13: Flokkur 3 eftir 5 ár | B13: =INDEX($J$7:$P$17,MATCH(A13,$I$7:$I$17,0),MATCH($B$1,$J$6:$P$6,0)) -> 840658.3 | C13: =ROUND(B13/162.5,0) -> 5173 | D13: =ROUND(B13*0.010385,0) -> 8730 | E13: =ROUND(B13*0.01375,0) -> 11559 | F13: =+C13+HLOOKUP($B$1,$R$6:$W$7,2,FALSE) -> 5280 | I13: Flokkur 3 eftir 5 ár | J13: 729141 | K13: 764766 | L13: 800391 | M13: 805033.27 | N13: 840658.3 | O13: 841163 | P13: 876696.52
A14: Flokkur 4 grunnlaun | B14: =INDEX($J$7:$P$17,MATCH(A14,$I$7:$I$17,0),MATCH($B$1,$J$6:$P$6,0)) -> 799660.9 | C14: =ROUND(B14/162.5,0) -> 4921 | D14: =ROUND(B14*0.010385,0) -> 8304 | E14: =ROUND(B14*0.01375,0) -> 10995 | F14: =+C14+HLOOKUP($B$1,$R$6:$W$7,2,FALSE) -> 5028 | I14: Flokkur 4 grunnlaun | J14: 688380 | K14: 724005 | L14: 759630 | M14: 764035.85 | N14: 799660.9 | O14: 800141 | P14: 835699.1
A15: Flokkur 4 eftir 1 ár | B15: =INDEX($J$7:$P$17,MATCH(A15,$I$7:$I$17,0),MATCH($B$1,$J$6:$P$6,0)) -> 830954.3 | C15: =ROUND(B15/162.5,0) -> 5114 | D15: =ROUND(B15*0.010385,0) -> 8629 | E15: =ROUND(B15*0.01375,0) -> 11426 | F15: =+C15+HLOOKUP($B$1,$R$6:$W$7,2,FALSE) -> 5221 | I15: Flokkur 4 eftir 1 ár | J15: 719493 | K15: 755118 | L15: 790743 | M15: 795329.31 | N15: 830954.3 | O15: 831453 | P15: 866992.56
A16: Flokkur 4 eftir 3 ár | B16: =INDEX($J$7:$P$17,MATCH(A16,$I$7:$I$17,0),MATCH($B$1,$J$6:$P$6,0)) -> 855544.6 | C16: =ROUND(B16/162.5,0) -> 5265 | D16: =ROUND(B16*0.010385,0) -> 8885 | E16: =ROUND(B16*0.01375,0) -> 11764 | F16: =+C16+HLOOKUP($B$1,$R$6:$W$7,2,FALSE) -> 5372 | I16: Flokkur 4 eftir 3 ár | J16: 743941 | K16: 779566.5 | L16: 815191.5 | M16: 819919.61 | N16: 855544.6 | O16: 856058 | P16: 891582.86
A17: Flokkur 4 eftir 5 ár | B17: =INDEX($J$7:$P$17,MATCH(A17,$I$7:$I$17,0),MATCH($B$1,$J$6:$P$6,0)) -> 867186.3 | C17: =ROUND(B17/162.5,0) -> 5337 | D17: =ROUND(B17*0.010385,0) -> 9006 | E17: =ROUND(B17*0.01375,0) -> 11924 | F17: =+C17+HLOOKUP($B$1,$R$6:$W$7,2,FALSE) -> 5444 | I17: Flokkur 4 eftir 5 ár | J17: 749529 | K17: 786654 | L17: 824529 | M17: 829311.27 | N17: 867186.3 | O17: 867707 | P17: 905500.62
A20: Launatafla með orlofi
B21: Mánaðarlaun | C21: Dagvinnukaup | D21: Yfirvinnukaup | E21: Stórhátíðakaup | F21: Dagvinnukaup með des/orlofsuppbót
A22: Flokkur 1 grunnlaun | B22: =B7*(1+$C$2) -> 789484 | C22: =ROUND(B22/162.5,0) -> 4858 | D22: =ROUND(B22*0.010385,0) -> 8199 | E22: =ROUND(B22*0.01375,0) -> 10855 | F22: =+C22+HLOOKUP($B$1,$R$6:$W$7,2,FALSE) -> 4965
A23: Flokkur 2 grunnlaun | B23: =B8*(1+$C$2) -> 789484 | C23: =ROUND(B23/162.5,0) -> 4858 | D23: =ROUND(B23*0.010385,0) -> 8199 | E23: =ROUND(B23*0.01375,0) -> 10855 | F23: =+C23+HLOOKUP($B$1,$R$6:$W$7,2,FALSE) -> 4965
A24: Flokkur 2 eftir 1 ár | B24: =B9*(1+$C$2) -> 793150.8 | C24: =ROUND(B24/162.5,0) -> 4881 | D24: =ROUND(B24*0.010385,0) -> 8237 | E24: =ROUND(B24*0.01375,0) -> 10906 | F24: =+C24+HLOOKUP($B$1,$R$6:$W$7,2,FALSE) -> 4988
A25: Flokkur 3 grunnlaun | B25: =B10*(1+$C$2) -> 793733.1 | C25: =ROUND(B25/162.5,0) -> 4885 | D25: =ROUND(B25*0.010385,0) -> 8243 | E25: =ROUND(B25*0.01375,0) -> 10914 | F25: =+C25+HLOOKUP($B$1,$R$6:$W$7,2,FALSE) -> 4992
A26: Flokkur 3 eftir 1 ár | B26: =B11*(1+$C$2) -> 811268.8 | C26: =ROUND(B26/162.5,0) -> 4992 | D26: =ROUND(B26*0.010385,0) -> 8425 | E26: =ROUND(B26*0.01375,0) -> 11155 | F26: =+C26+HLOOKUP($B$1,$R$6:$W$7,2,FALSE) -> 5099
A27: Flokkur 3 eftir 3 ár | B27: =B12*(1+$C$2) -> 835190.7 | C27: =ROUND(B27/162.5,0) -> 5140 | D27: =ROUND(B27*0.010385,0) -> 8673 | E27: =ROUND(B27*0.01375,0) -> 11484 | F27: =+C27+HLOOKUP($B$1,$R$6:$W$7,2,FALSE) -> 5247
A28: Flokkur 3 eftir 5 ár | B28: =B13*(1+$C$2) -> 840658.3 | C28: =ROUND(B28/162.5,0) -> 5173 | D28: =ROUND(B28*0.010385,0) -> 8730 | E28: =ROUND(B28*0.01375,0) -> 11559 | F28: =+C28+HLOOKUP($B$1,$R$6:$W$7,2,FALSE) -> 5280
A29: Flokkur 4 grunnlaun | B29: =B14*(1+$C$2) -> 799660.9 | C29: =ROUND(B29/162.5,0) -> 4921 | D29: =ROUND(B29*0.010385,0) -> 8304 | E29: =ROUND(B29*0.01375,0) -> 10995 | F29: =+C29+HLOOKUP($B$1,$R$6:$W$7,2,FALSE) -> 5028
A30: Flokkur 4 eftir 1 ár | B30: =B15*(1+$C$2) -> 830954.3 | C30: =ROUND(B30/162.5,0) -> 5114 | D30: =ROUND(B30*0.010385,0) -> 8629 | E30: =ROUND(B30*0.01375,0) -> 11426 | F30: =+C30+HLOOKUP($B$1,$R$6:$W$7,2,FALSE) -> 5221
A31: Flokkur 4 eftir 3 ár | B31: =B16*(1+$C$2) -> 855544.6 | C31: =ROUND(B31/162.5,0) -> 5265 | D31: =ROUND(B31*0.010385,0) -> 8885 | E31: =ROUND(B31*0.01375,0) -> 11764 | F31: =+C31+HLOOKUP($B$1,$R$6:$W$7,2,FALSE) -> 5372
A32: Flokkur 4 eftir 5 ár | B32: =B17*(1+$C$2) -> 867186.3 | C32: =ROUND(B32/162.5,0) -> 5337 | D32: =ROUND(B32*0.010385,0) -> 9006 | E32: =ROUND(B32*0.01375,0) -> 11924 | F32: =+C32+HLOOKUP($B$1,$R$6:$W$7,2,FALSE) -> 5444
A35: Dagsferðir
C36: Lengd ferðar -> | D36: 4 kist. | E36: 4 kist. | F36: 5 klst. | G36: 5 klst. | H36: 6 klst. | I36: 6 klst. | J36: 7 klst. | K36: 7 klst. | L36: 8 klst. | M36: 8 klst. | N36: 9 klst | O36: 9 klst | P36: 10 klst. | Q36: 10 klst. | R36: 11 kist. | S36: 11 kist. | T36: 12 klst. | U36: 12 klst.
B37: Dagvinna | C37: Yfirvinna | D37: mán-föst | E37: lau-sun | F37: mán-föst | G37: lau-sun | H37: mán-föst | I37: lau-sun | J37: mán-föst | K37: lau-sun | L37: mán-föst | M37: lau-sun | N37: mán-föst | O37: lau-sun | P37: mán-föst | Q37: lau-sun | R37: mán-föst | S37: lau-sun | T37: mán-föst | U37: lau-sun
A38: Flokkur 1 grunnlaun | B38: =C22 -> 4858 | C38: =D22 -> 8199 | D38: =D$51*($B38) -> 19432 | E38: =E$51*($C38) -> 32796 | F38: =F$51*($B38) -> 24290 | G38: =G$51*($C38) -> 40995 | H38: =H$51*($B38) -> 29148 | I38: =I$51*($C38) -> 49194 | J38: =J$51*($B38) -> 34006 | K38: =K$51*($C38) -> 57393 | L38: =MIN(L$51,7.5)*$B38+(L$51-7.5)*$C38 -> 40534.5 | M38: =M$51*($C38) -> 65592 | N38: =MIN(N$51,7.5)*$B38+(N$51-7.5)*$C38 -> 48733.5 | O38: =O$51*($C38) -> 73791 | P38: =MIN(P$51,7.5)*$B38+(P$51-7.5)*$C38 -> 56932.5 | Q38: =Q$51*($C38) -> 81990 | R38: =MIN(R$51,7.5)*$B38+(R$51-7.5)*$C38 -> 65131.5 | S38: =S$51*($C38) -> 90189 | T38: =MIN(T$51,7.5)*$B38+(T$51-7.5)*$C38 -> 73330.5 | U38: =U$51*($C38) -> 98388
A39: Flokkur 2 grunnlaun | B39: =C23 -> 4858 | C39: =D23 -> 8199 | D39: =D$51*($B39) -> 19432 | E39: =E$51*($C39) -> 32796 | F39: =F$51*($B39) -> 24290 | G39: =G$51*($C39) -> 40995 | H39: =H$51*($B39) -> 29148 | I39: =I$51*($C39) -> 49194 | J39: =J$51*($B39) -> 34006 | K39: =K$51*($C39) -> 57393 | L39: =MIN(L$51,7.5)*$B39+(L$51-7.5)*$C39 -> 40534.5 | M39: =M$51*($C39) -> 65592 | N39: =MIN(N$51,7.5)*$B39+(N$51-7.5)*$C39 -> 48733.5 | O39: =O$51*($C39) -> 73791 | P39: =MIN(P$51,7.5)*$B39+(P$51-7.5)*$C39 -> 56932.5 | Q39: =Q$51*($C39) -> 81990 | R39: =MIN(R$51,7.5)*$B39+(R$51-7.5)*$C39 -> 65131.5 | S39: =S$51*($C39) -> 90189 | T39: =MIN(T$51,7.5)*$B39+(T$51-7.5)*$C39 -> 73330.5 | U39: =U$51*($C39) -> 98388
A40: Flokkur 2 eftir 1 ár | B40: =C24 -> 4881 | C40: =D24 -> 8237 | D40: =D$51*($B40) -> 19524 | E40: =E$51*($C40) -> 32948 | F40: =F$51*($B40) -> 24405 | G40: =G$51*($C40) -> 41185 | H40: =H$51*($B40) -> 29286 | I40: =I$51*($C40) -> 49422 | J40: =J$51*($B40) -> 34167 | K40: =K$51*($C40) -> 57659 | L40: =MIN(L$51,7.5)*$B40+(L$51-7.5)*$C40 -> 40726 | M40: =M$51*($C40) -> 65896 | N40: =MIN(N$51,7.5)*$B40+(N$51-7.5)*$C40 -> 48963 | O40: =O$51*($C40) -> 74133 | P40: =MIN(P$51,7.5)*$B40+(P$51-7.5)*$C40 -> 57200 | Q40: =Q$51*($C40) -> 82370 | R40: =MIN(R$51,7.5)*$B40+(R$51-7.5)*$C40 -> 65437 | S40: =S$51*($C40) -> 90607 | T40: =MIN(T$51,7.5)*$B40+(T$51-7.5)*$C40 -> 73674 | U40: =U$51*($C40) -> 98844
A41: Flokkur 3 grunnlaun | B41: =C25 -> 4885 | C41: =D25 -> 8243 | D41: =D$51*($B41) -> 19540 | E41: =E$51*($C41) -> 32972 | F41: =F$51*($B41) -> 24425 | G41: =G$51*($C41) -> 41215 | H41: =H$51*($B41) -> 29310 | I41: =I$51*($C41) -> 49458 | J41: =J$51*($B41) -> 34195 | K41: =K$51*($C41) -> 57701 | L41: =MIN(L$51,7.5)*$B41+(L$51-7.5)*$C41 -> 40759 | M41: =M$51*($C41) -> 65944 | N41: =MIN(N$51,7.5)*$B41+(N$51-7.5)*$C41 -> 49002 | O41: =O$51*($C41) -> 74187 | P41: =MIN(P$51,7.5)*$B41+(P$51-7.5)*$C41 -> 57245 | Q41: =Q$51*($C41) -> 82430 | R41: =MIN(R$51,7.5)*$B41+(R$51-7.5)*$C41 -> 65488 | S41: =S$51*($C41) -> 90673 | T41: =MIN(T$51,7.5)*$B41+(T$51-7.5)*$C41 -> 73731 | U41: =U$51*($C41) -> 98916
A42: Flokkur 3 eftir 1 ár | B42: =C26 -> 4992 | C42: =D26 -> 8425 | D42: =D$51*($B42) -> 19968 | E42: =E$51*($C42) -> 33700 | F42: =F$51*($B42) -> 24960 | G42: =G$51*($C42) -> 42125 | H42: =H$51*($B42) -> 29952 | I42: =I$51*($C42) -> 50550 | J42: =J$51*($B42) -> 34944 | K42: =K$51*($C42) -> 58975 | L42: =MIN(L$51,7.5)*$B42+(L$51-7.5)*$C42 -> 41652.5 | M42: =M$51*($C42) -> 67400 | N42: =MIN(N$51,7.5)*$B42+(N$51-7.5)*$C42 -> 50077.5 | O42: =O$51*($C42) -> 75825 | P42: =MIN(P$51,7.5)*$B42+(P$51-7.5)*$C42 -> 58502.5 | Q42: =Q$51*($C42) -> 84250 | R42: =MIN(R$51,7.5)*$B42+(R$51-7.5)*$C42 -> 66927.5 | S42: =S$51*($C42) -> 92675 | T42: =MIN(T$51,7.5)*$B42+(T$51-7.5)*$C42 -> 75352.5 | U42: =U$51*($C42) -> 101100
A43: Flokkur 3 eftir 3 ár | B43: =C27 -> 5140 | C43: =D27 -> 8673 | D43: =D$51*($B43) -> 20560 | E43: =E$51*($C43) -> 34692 | F43: =F$51*($B43) -> 25700 | G43: =G$51*($C43) -> 43365 | H43: =H$51*($B43) -> 30840 | I43: =I$51*($C43) -> 52038 | J43: =J$51*($B43) -> 35980 | K43: =K$51*($C43) -> 60711 | L43: =MIN(L$51,7.5)*$B43+(L$51-7.5)*$C43 -> 42886.5 | M43: =M$51*($C43) -> 69384 | N43: =MIN(N$51,7.5)*$B43+(N$51-7.5)*$C43 -> 51559.5 | O43: =O$51*($C43) -> 78057 | P43: =MIN(P$51,7.5)*$B43+(P$51-7.5)*$C43 -> 60232.5 | Q43: =Q$51*($C43) -> 86730 | R43: =MIN(R$51,7.5)*$B43+(R$51-7.5)*$C43 -> 68905.5 | S43: =S$51*($C43) -> 95403 | T43: =MIN(T$51,7.5)*$B43+(T$51-7.5)*$C43 -> 77578.5 | U43: =U$51*($C43) -> 104076
A44: Flokkur 3 eftir 5 ár | B44: =C28 -> 5173 | C44: =D28 -> 8730 | D44: =D$51*($B44) -> 20692 | E44: =E$51*($C44) -> 34920 | F44: =F$51*($B44) -> 25865 | G44: =G$51*($C44) -> 43650 | H44: =H$51*($B44) -> 31038 | I44: =I$51*($C44) -> 52380 | J44: =J$51*($B44) -> 36211 | K44: =K$51*($C44) -> 61110 | L44: =MIN(L$51,7.5)*$B44+(L$51-7.5)*$C44 -> 43162.5 | M44: =M$51*($C44) -> 69840 | N44: =MIN(N$51,7.5)*$B44+(N$51-7.5)*$C44 -> 51892.5 | O44: =O$51*($C44) -> 78570 | P44: =MIN(P$51,7.5)*$B44+(P$51-7.5)*$C44 -> 60622.5 | Q44: =Q$51*($C44) -> 87300 | R44: =MIN(R$51,7.5)*$B44+(R$51-7.5)*$C44 -> 69352.5 | S44: =S$51*($C44) -> 96030 | T44: =MIN(T$51,7.5)*$B44+(T$51-7.5)*$C44 -> 78082.5 | U44: =U$51*($C44) -> 104760
A45: Flokkur 4 grunnlaun | B45: =C29 -> 4921 | C45: =D29 -> 8304 | D45: =D$51*($B45) -> 19684 | E45: =E$51*($C45) -> 33216 | F45: =F$51*($B45) -> 24605 | G45: =G$51*($C45) -> 41520 | H45: =H$51*($B45) -> 29526 | I45: =I$51*($C45) -> 49824 | J45: =J$51*($B45) -> 34447 | K45: =K$51*($C45) -> 58128 | L45: =MIN(L$51,7.5)*$B45+(L$51-7.5)*$C45 -> 41059.5 | M45: =M$51*($C45) -> 66432 | N45: =MIN(N$51,7.5)*$B45+(N$51-7.5)*$C45 -> 49363.5 | O45: =O$51*($C45) -> 74736 | P45: =MIN(P$51,7.5)*$B45+(P$51-7.5)*$C45 -> 57667.5 | Q45: =Q$51*($C45) -> 83040 | R45: =MIN(R$51,7.5)*$B45+(R$51-7.5)*$C45 -> 65971.5 | S45: =S$51*($C45) -> 91344 | T45: =MIN(T$51,7.5)*$B45+(T$51-7.5)*$C45 -> 74275.5 | U45: =U$51*($C45) -> 99648
A46: Flokkur 4 eftir 1 ár | B46: =C30 -> 5114 | C46: =D30 -> 8629 | D46: =D$51*($B46) -> 20456 | E46: =E$51*($C46) -> 34516 | F46: =F$51*($B46) -> 25570 | G46: =G$51*($C46) -> 43145 | H46: =H$51*($B46) -> 30684 | I46: =I$51*($C46) -> 51774 | J46: =J$51*($B46) -> 35798 | K46: =K$51*($C46) -> 60403 | L46: =MIN(L$51,7.5)*$B46+(L$51-7.5)*$C46 -> 42669.5 | M46: =M$51*($C46) -> 69032 | N46: =MIN(N$51,7.5)*$B46+(N$51-7.5)*$C46 -> 51298.5 | O46: =O$51*($C46) -> 77661 | P46: =MIN(P$51,7.5)*$B46+(P$51-7.5)*$C46 -> 59927.5 | Q46: =Q$51*($C46) -> 86290 | R46: =MIN(R$51,7.5)*$B46+(R$51-7.5)*$C46 -> 68556.5 | S46: =S$51*($C46) -> 94919 | T46: =MIN(T$51,7.5)*$B46+(T$51-7.5)*$C46 -> 77185.5 | U46: =U$51*($C46) -> 103548
...

Sheet Launaflokkur - skyring
A2: Launaflokkur 1 | B2: Fararstjóri, hópstjóri. Er fulltrúi ferðaskrifstofu og veitir ferðamönnum hagnýta þjónustu í samræmi við óskir ferðaskrifstofu.
A3: Launaflokkur 2 | B3: Leiðsögumaður án sérstakrar menntunar á sviði leiðsagnar eða annars starfsundirbúnings fyrir leiðsögustörf.
A4: Launaflokkur 3 | B4: Leiðsögumaður með starfsundirbúning (menntun eða raunfærnimat) á sérsviði leiðsagnar eða í almennri leiðsögn sem nýtist í starfi. Getur forgangsraðað og skipulagt eigin störf í krefjandi aðstæðum og sýnt fagmennsku í starfi. Getur miðlað þekkingu sinni og leikni, rökstutt og ígrundað þær aðferðir sem hann nýtir auk þess að búa yfir ábyrgð gagnvart starfsumhverfi og hæfni til að leiðbeina öðrum.
A5: Launaflokkur 4 | B5: Leiðsögumaður með starfsundirbúning fyrir almenna leiðsögn (menntun eða raunfærnimat) í samræmi við IST EN 15565:2008 um þjálfun og menntun leiðsögumanna sem nýtist í starfi, með próf í leiðsögn. Hefur sérhæfða þekkingu sem nýtist við leiðsögn. Getur forgangsraðað og skipulagt eigin störf í krefjandi aðstæðum og sýnt fagmennsku í starfi. Getur miðlað þekkingu sinni og leikni, rökstutt og ígrundað þær aðferðir sem hann nýtir auk þess að búa yfir ábyrgð gagnvart starfsumhverfi og hæfni til að leiðbeina öðrum.
